{"name": "test_InvalidUser_ErrorMessageShown", "status": "passed", "description": "Login with invalid credentials and check that username error message is shown", "attachments": [{"name": "log", "source": "9dfed3c6-ffb3-45af-9bdf-0b61d4306e9b-attachment.txt", "type": "text/plain"}], "start": 1745227499097, "stop": 1745227499609, "uuid": "ca87463d-cba6-4f18-86ef-241801c45872", "historyId": "a5e4a4d72e174d211f0da7cc743eda45", "testCaseId": "a5e4a4d72e174d211f0da7cc743eda45", "fullName": "tests.test_login.TestLogin#test_InvalidUser_ErrorMessageShown", "labels": [{"name": "severity", "value": "normal"}, {"name": "parentSuite", "value": "tests"}, {"name": "suite", "value": "test_login"}, {"name": "subSuite", "value": "TestLogin"}, {"name": "host", "value": "User-PC"}, {"name": "thread", "value": "10716-MainThread"}, {"name": "framework", "value": "pytest"}, {"name": "language", "value": "cpython3"}, {"name": "package", "value": "tests.test_login"}]}