{"name": "test_additionPositiveNumbers_SuccessfulLoginAndValidResult", "status": "failed", "statusDetails": {"message": "AssertionError: Expected '8', but got \nassert '8' == ''\n  + 8", "trace": "self = <test_calc.TestCalculate object at 0x00000168692C3500>\n\n    def test_additionPositiveNumbers_SuccessfulLoginAndValidResult(self):\n        logging.info('trying to log in as valid user')\n        self.login_page.log_in('admin','123')\n        logging.info('trying to add up for positive numbers')\n        self.calculator_page.calc_add('5','3')\n        logging.info('checking the receipt of the calculation result')\n        result = self.calculator_page.get_result()\n>       assert '8' == self.calculator_page.get_result(), f\"Expected '8', but got {self.calculator_page.get_result()}\"\nE       AssertionError: Expected '8', but got \nE       assert '8' == ''\nE         + 8\n\ntest_calc.py:47: AssertionError"}, "attachments": [{"name": "log", "source": "72c98e88-b96c-4be1-8230-8ef69b34c1d5-attachment.txt", "type": "text/plain"}], "start": 1745345539253, "stop": 1745345539818, "uuid": "50213953-01b8-4120-a3b2-b743677bd582", "historyId": "017c2c166afb58f0ef9ef9f053aa6151", "testCaseId": "017c2c166afb58f0ef9ef9f053aa6151", "fullName": "tests.test_calc.TestCalculate#test_additionPositiveNumbers_SuccessfulLoginAndValidResult", "labels": [{"name": "parentSuite", "value": "tests"}, {"name": "suite", "value": "test_calc"}, {"name": "subSuite", "value": "TestCalculate"}, {"name": "host", "value": "User-PC"}, {"name": "thread", "value": "3672-MainThread"}, {"name": "framework", "value": "pytest"}, {"name": "language", "value": "cpython3"}, {"name": "package", "value": "tests.test_calc"}]}