{"name": "test_InvalidUser_ErrorMessageShown", "status": "passed", "description": "Login with invalid credentials and check that username error message is shown", "attachments": [{"source": "9434e89c-d566-4ed5-b267-19105f0e192e-attachment.png", "type": "image/png"}, {"name": "log", "source": "ebbd912f-0e27-4e6e-80d7-0b417ccf6097-attachment.txt", "type": "text/plain"}], "start": 1745067939650, "stop": 1745067940079, "uuid": "3a2963d8-cde3-4361-8b45-5fdd24ad3c98", "historyId": "a5e4a4d72e174d211f0da7cc743eda45", "testCaseId": "a5e4a4d72e174d211f0da7cc743eda45", "fullName": "tests.test_login.TestLogin#test_InvalidUser_ErrorMessageShown", "labels": [{"name": "severity", "value": "normal"}, {"name": "parentSuite", "value": "tests"}, {"name": "suite", "value": "test_login"}, {"name": "subSuite", "value": "TestLogin"}, {"name": "host", "value": "User-PC"}, {"name": "thread", "value": "5460-MainThread"}, {"name": "framework", "value": "pytest"}, {"name": "language", "value": "cpython3"}, {"name": "package", "value": "tests.test_login"}]}